Workbook

Sheet Бали кандидатів
A1: КАЛЬКУЛЯТОР КОНКУРСНОГО БАЛА — аспірантура F3 «Комп'ютерні науки», 2026
A3: ЖОВТІ клітинки заповнюєте ви. Два стовпці — два кандидати; таблиця рахує обидва одночасно.
A5: ПОКАЗНИК | B5: КАНДИДАТ 1 | C5: КАНДИДАТ 2 | D5: Пояснення
A6: ЄВІ — тест з іноземної мови (П1) | B6: 174 | C6: 167 | D6: Кандидат 2: фактичний результат ЄВІ-іноземна 167.
A7: ЄВВ — методологія наукових досліджень (П2) | B7: 158.5 | C7: 142 | D7: Кандидат 2: фактичний результат 142. УВАГА: нижче 150 — не проходить туди, де ЗВО підняв мін. бал за ЄВВ до 150 (напр. Інститут проблем моделювання в енергетиці НАНУ).
A8: ТЗНК (для допуску, вага 0) | B8: 182 | C8: 175 | D8: Кандидат 2: фактичний результат 175. У формулу КБ не входить, лише допуск.
A9: Очікуваний бал за іспит зі спеціальності | B9: 160 | C9: 160 | D9: ОЦІНКА, а не факт. Змініть — і вся таблиця перерахується.
A10: Очікуваний бал за дослідницьку пропозицію | B10: 180 | C10: 150 | D10: Там, де вона оцінюється.
A11: Очікуваний бал за додатковий іспит (філософія тощо) | B11: 150 | C11: 150 | D11: Стосується лише ЖДУ ім. Франка та Одеської юракадемії.
A13: ПЕРЕВІРКА ДОПУСКУ (ТЗНК + іноземна >= 300)
A14: Сума | B14: =B8+B6 | C14: =C8+C6 | D14: =IF(AND(B14>=300,C14>=300),"обидва допущені",IF(B14>=300,"К2 НЕ допущений",IF(C14>=300,"К1 НЕ допущений","обидва НЕ допущені")))
A16: ФОРМУЛА (Порядок прийому 2026, вступ до аспірантури)
A17: КБ = 0,2 × іноземна ЄВІ + 0,2 × ЄВВ + 0,6 × фахові випробування (іспит + пропозиція + дод. іспит)
A18: ТЗНК має вагу 0 і в конкурсний бал не входить — лише допуск.
A20: !! «Ліцензований обсяг» на аркуші розрахунку — це ЄМНІСТЬ ЗА ЛІЦЕНЗІЄЮ, а не кількість бюджетних місць.
A21: Розподіл держзамовлення між ЗВО торік відбувся 15 вересня — тобто вже після дедлайну подачі заяв.
A23: УВАГА, КАНДИДАТ 2. Пріоритет — НУ «Запорізька політехніка», «Електронна інженерія». Це галузь «Інженерія, виробництво та будівництво», а НЕ «Інформаційні технології»: аркуш «Розрахунок по ЗВО» покриває лише F1-F7 і цієї пропозиції не містить. Квота держзамовлення на IT (769 місць) до неї теж не стосується — електроніка фінансується з іншої галузевої квоти.
A24: Ваги випробувань у «Електронній інженерії» майже напевно інші, ніж у F3. Поки пропозицію не вивантажено зі «Вступ.ОСВІТА.UA», КБ по ній не рахується.

Sheet Розрахунок по ЗВО
A1: СПЕЦІАЛЬНІСТЬ | B1: ЗВО | C1: Місто | D1: Регіон | E1: Денна бюджетна? | F1: Тип пропозиції | G1: Переміщений ЗВО | H1: Примітка про переміщення | I1: Освітня програма | J1: Факультет | K1: Ліцензований обсяг (НЕ дорівнює кількості бюджетних місць) | L1: Заяв | M1: Заяв на 1 ліценз. місце | N1: Дані станом на | O1: k іспит | P1: k пропозиція | Q1: k дод. | R1: Мін. бал іспит | S1: Мін. бал пропоз. | T1: КБ — кандидат 1 | U1: КБ — кандидат 2 | V1: Допуск К1 | W1: Допуск К2 | X1: Пороги К1 | Y1: Пороги К2 | Z1: Тип відбору | AA1: Інші випробування / нюанси | AB1: ДАТА іспиту зі спец. | AC1: ЧАС іспиту | AD1: МІСЦЕ / формат складання | AE1: Контакти | AF1: Сторінка пропозиції | AG1: Дистанційно? | AH1: Приїздів/рік | AI1: Запит/відповідь | AJ1: Мін. бал ЄВВ | AK1: Мін. бал іноземної | AL1: Мін. бал ТЗНК | AM1: Допуск ЄВВ К1 | AN1: Допуск ЄВВ К2
A2: F3 Комп'ютерні науки | B2: Інститут проблем моделювання в енергетиці ім. Г. Є. Пухова НАНУ | C2: Київ | D2: Київ | E2: ТАК | F2: Фіксована | G2: ні | I2: Комп'ютерні науки | K2: 13 | L2: 10 | M2: =IF(K2=0,"н/д",L2/K2) | N2: 26.08.2026 | O2: 0.6 | P2: 0 | Q2: 0 | R2: — | S2: — | T2: =0.2*'Бали кандидатів'!$B$6+0.2*'Бали кандидатів'!$B$7+O2*'Бали кандидатів'!$B$9+P2*'Бали кандидатів'!$B$10+Q2*'Бали кандидатів'!$B$11 | U2: =0.2*'Бали кандидатів'!$C$6+0.2*'Бали кандидатів'!$C$7+O2*'Бали кандидатів'!$C$9+P2*'Бали кандидатів'!$C$10+Q2*'Бали кандидатів'!$C$11 | V2: =IF('Бали кандидатів'!$B$14>=300,"OK","НЕ ДОПУЩЕНО") | W2: =IF('Бали кандидатів'!$C$14>=300,"OK","НЕ ДОПУЩЕНО") | X2: =IF(AND(OR(R2="—",'Бали кандидатів'!$B$9>=R2),OR(S2="—",'Бали кандидатів'!$B$10>=S2)),"проходить","НИЖЧЕ мін. балу") | Y2: =IF(AND(OR(R2="—",'Бали кандидатів'!$C$9>=R2),OR(S2="—",'Бали кандидатів'!$C$10>=S2)),"проходить","НИЖЧЕ мін. балу") | Z2: Тільки іспит зі спеціальності | AA2: Мін. бал за ЄВВ підвищено до 150 (у вас 158.5 — проходить) | AE2: https://vstup.osvita.ua/r27/3487/entrance.html | AF2: https://vstup.osvita.ua/y2026/r27/3487/1654421/ | AM2: =IF(AJ2="","дані ще не вивантажені",IF('Бали кандидатів'!$B$7>=AJ2,"проходить","НЕ проходить за ЄВВ")) | AN2: =IF(AJ2="","дані ще не вивантажені",IF('Бали кандидатів'!$C$7>=AJ2,"проходить","НЕ проходить за ЄВВ"))
A3: F3 Комп'ютерні науки | B3: Харківський національний університет ім. В. Н. Каразіна | C3: Харків | D3: Харківська | E3: ТАК | F3: Фіксована | G3: ні | I3: Комп'ютерні науки | J3: Математики і інформатики | K3: 10 | L3: 9 | M3: =IF(K3=0,"н/д",L3/K3) | N3: 25.08.2026 (застаріле) | O3: 0.2 | P3: 0.4 | Q3: 0 | R3: 100 | S3: 100 | T3: =0.2*'Бали кандидатів'!$B$6+0.2*'Бали кандидатів'!$B$7+O3*'Бали кандидатів'!$B$9+P3*'Бали кандидатів'!$B$10+Q3*'Бали кандидатів'!$B$11 | U3: =0.2*'Бали кандидатів'!$C$6+0.2*'Бали кандидатів'!$C$7+O3*'Бали кандидатів'!$C$9+P3*'Бали кандидатів'!$C$10+Q3*'Бали кандидатів'!$C$11 | V3: =IF('Бали кандидатів'!$B$14>=300,"OK","НЕ ДОПУЩЕНО") | W3: =IF('Бали кандидатів'!$C$14>=300,"OK","НЕ ДОПУЩЕНО") | X3: =IF(AND(OR(R3="—",'Бали кандидатів'!$B$9>=R3),OR(S3="—",'Бали кандидатів'!$B$10>=S3)),"проходить","НИЖЧЕ мін. балу") | Y3: =IF(AND(OR(R3="—",'Бали кандидатів'!$C$9>=R3),OR(S3="—",'Бали кандидатів'!$C$10>=S3)),"проходить","НИЖЧЕ мін. балу") | Z3: Дослідницька пропозиція важить більше або нарівні з іспитом | AA3: Плюс додатковий іспит зі спеціальності (вага 0) | AE3: https://vstup.osvita.ua/r21/62/entrance.html | AF3: https://vstup.osvita.ua/y2026/r21/62/1652199/ | AM3: =IF(AJ3="","дані ще не вивантажені",IF('Бали кандидатів'!$B$7>=AJ3,"проходить","НЕ проходить за ЄВВ")) | AN3: =IF(AJ3="","дані ще не вивантажені",IF('Бали кандидатів'!$C$7>=AJ3,"проходить","НЕ проходить за ЄВВ"))
A4: F4 Системний аналіз | B4: НУ «Львівська політехніка» | C4: Львів | D4: Львівська | E4: ТАК | F4: Фіксована | G4: ні | I4: Системний аналіз та наука про дані | J4: Інститут комп. наук та інформаційних технологій | K4: 23 | L4: 21 | M4: =IF(K4=0,"н/д",L4/K4) | N4: 26.08.2026 | O4: ? | P4: ? | Q4: ? | R4: ? | S4: ? | T4: ваги невідомі | U4: ваги невідомі | V4: =IF('Бали кандидатів'!$B$14>=300,"OK","НЕ ДОПУЩЕНО") | W4: =IF('Бали кандидатів'!$C$14>=300,"OK","НЕ ДОПУЩЕНО") | X4: — | Y4: — | Z4: ваги не зчитані — уточнити на сторінці пропозиції | AA4: Складові конкурсного бала у вихідних даних відсутні — відкрити «Детальніше» на сторінці ЗВО | AB4: 09.09.2026 | AC4: 14:30 | AD4: I навчальний корпус, вул. Старосольських 2/4, Львів (ІКНІ) | AE4: https://vstup.osvita.ua/r14/97/entrance.html | AF4: https://vstup.osvita.ua/r14/97/ | AM4: =IF(AJ4="","дані ще не вивантажені",IF('Бали кандидатів'!$B$7>=AJ4,"проходить","НЕ проходить за ЄВВ")) | AN4: =IF(AJ4="","дані ще не вивантажені",IF('Бали кандидатів'!$C$7>=AJ4,"проходить","НЕ проходить за ЄВВ"))
A5: F3 Комп'ютерні науки | B5: Інститут прикладних систем управління НАНУ | C5: Київ | D5: Київ | E5: ТАК | F5: Фіксована | G5: ні | I5: Комп'ютерні науки | K5: 7 | L5: 7 | M5: =IF(K5=0,"н/д",L5/K5) | N5: 26.08.2026 | O5: 0.3 | P5: 0.3 | Q5: 0 | R5: — | S5: — | T5: =0.2*'Бали кандидатів'!$B$6+0.2*'Бали кандидатів'!$B$7+O5*'Бали кандидатів'!$B$9+P5*'Бали кандидатів'!$B$10+Q5*'Бали кандидатів'!$B$11 | U5: =0.2*'Бали кандидатів'!$C$6+0.2*'Бали кандидатів'!$C$7+O5*'Бали кандидатів'!$C$9+P5*'Бали кандидатів'!$C$10+Q5*'Бали кандидатів'!$C$11 | V5: =IF('Бали кандидатів'!$B$14>=300,"OK","НЕ ДОПУЩЕНО") | W5: =IF('Бали кандидатів'!$C$14>=300,"OK","НЕ ДОПУЩЕНО") | X5: =IF(AND(OR(R5="—",'Бали кандидатів'!$B$9>=R5),OR(S5="—",'Бали кандидатів'!$B$10>=S5)),"проходить","НИЖЧЕ мін. балу") | Y5: =IF(AND(OR(R5="—",'Бали кандидатів'!$C$9>=R5),OR(S5="—",'Бали кандидатів'!$C$10>=S5)),"проходить","НИЖЧЕ мін. балу") | Z5: Дослідницька пропозиція важить більше або нарівні з іспитом | AE5: https://vstup.osvita.ua/r27/7303/entrance.html | AF5: https://vstup.osvita.ua/y2026/r27/7303/1669043/ | AM5: =IF(AJ5="","дані ще не вивантажені",IF('Бали кандидатів'!$B$7>=AJ5,"проходить","НЕ проходить за ЄВВ")) | AN5: =IF(AJ5="","дані ще не вивантажені",IF('Бали кандидатів'!$C$7>=AJ5,"проходить","НЕ проходить за ЄВВ"))
A6: F2 Інженерія ПЗ | B6: НУ «Чернігівська політехніка» | C6: Чернігів | D6: Чернігівська | E6: ТАК | F6: Фіксована | G6: ні | I6: Інженерія програмного забезпечення | J6: Аспірантура | K6: 5 | L6: 5 | M6: =IF(K6=0,"н/д",L6/K6) | N6: 26.08.2026 | O6: 0.6 | P6: 0 | Q6: 0 | R6: — | S6: — | T6: =0.2*'Бали кандидатів'!$B$6+0.2*'Бали кандидатів'!$B$7+O6*'Бали кандидатів'!$B$9+P6*'Бали кандидатів'!$B$10+Q6*'Бали кандидатів'!$B$11 | U6: =0.2*'Бали кандидатів'!$C$6+0.2*'Бали кандидатів'!$C$7+O6*'Бали кандидатів'!$C$9+P6*'Бали кандидатів'!$C$10+Q6*'Бали кандидатів'!$C$11 | V6: =IF('Бали кандидатів'!$B$14>=300,"OK","НЕ ДОПУЩЕНО") | W6: =IF('Бали кандидатів'!$C$14>=300,"OK","НЕ ДОПУЩЕНО") | X6: =IF(AND(OR(R6="—",'Бали кандидатів'!$B$9>=R6),OR(S6="—",'Бали кандидатів'!$B$10>=S6)),"проходить","НИЖЧЕ мін. балу") | Y6: =IF(AND(OR(R6="—",'Бали кандидатів'!$C$9>=R6),OR(S6="—",'Бали кандидатів'!$C$10>=S6)),"проходить","НИЖЧЕ мін. балу") | Z6: Тільки іспит зі спеціальності | AE6: https://vstup.osvita.ua/r26/140/entrance.html | AF6: https://vstup.osvita.ua/y2026/r26/140/1642941/ | AM6: =IF(AJ6="","дані ще не вивантажені",IF('Бали кандидатів'!$B$7>=AJ6,"проходить","НЕ проходить за ЄВВ")) | AN6: =IF(AJ6="","дані ще не вивантажені",IF('Бали кандидатів'!$C$7>=AJ6,"проходить","НЕ проходить за ЄВВ"))
A7: F2 Інженерія ПЗ | B7: Ужгородський національний університет | C7: Ужгород | D7: Закарпатська | E7: ТАК | F7: Фіксована | G7: ні | I7: Інженерія програмного забезпечення | J7: Факультет інформаційних технологій | K7: 8 | L7: 8 | M7: =IF(K7=0,"н/д",L7/K7) | N7: 26.08.2026 | O7: 0.4 | P7: 0.2 | Q7: 0 | R7: 100 | S7: 100 | T7: =0.2*'Бали кандидатів'!$B$6+0.2*'Бали кандидатів'!$B$7+O7*'Бали кандидатів'!$B$9+P7*'Бали кандидатів'!$B$10+Q7*'Бали кандидатів'!$B$11 | U7: =0.2*'Бали кандидатів'!$C$6+0.2*'Бали кандидатів'!$C$7+O7*'Бали кандидатів'!$C$9+P7*'Бали кандидатів'!$C$10+Q7*'Бали кандидатів'!$C$11 | V7: =IF('Бали кандидатів'!$B$14>=300,"OK","НЕ ДОПУЩЕНО") | W7: =IF('Бали кандидатів'!$C$14>=300,"OK","НЕ ДОПУЩЕНО") | X7: =IF(AND(OR(R7="—",'Бали кандидатів'!$B$9>=R7),OR(S7="—",'Бали кандидатів'!$B$10>=S7)),"проходить","НИЖЧЕ мін. балу") | Y7: =IF(AND(OR(R7="—",'Бали кандидатів'!$C$9>=R7),OR(S7="—",'Бали кандидатів'!$C$10>=S7)),"проходить","НИЖЧЕ мін. балу") | Z7: Іспит + дослідницька пропозиція | AE7: https://vstup.osvita.ua/r8/207/entrance.html | AF7: https://vstup.osvita.ua/y2026/r8/207/1643043/ | AM7: =IF(AJ7="","дані ще не вивантажені",IF('Бали кандидатів'!$B$7>=AJ7,"проходить","НЕ проходить за ЄВВ")) | AN7: =IF(AJ7="","дані ще не вивантажені",IF('Бали кандидатів'!$C$7>=AJ7,"проходить","НЕ проходить за ЄВВ"))
A8: F2 Інженерія ПЗ | B8: МАУП (Міжрегіональна Академія управління персоналом) | C8: Київ | D8: Київ | E8: ТАК | F8: Фіксована | G8: ні | I8: Інженерія програмного забезпечення | K8: 15 | L8: 15 | M8: =IF(K8=0,"н/д",L8/K8) | N8: 26.08.2026 | O8: 0.3 | P8: 0.3 | Q8: 0 | R8: 100 | S8: 100 | T8: =0.2*'Бали кандидатів'!$B$6+0.2*'Бали кандидатів'!$B$7+O8*'Бали кандидатів'!$B$9+P8*'Бали кандидатів'!$B$10+Q8*'Бали кандидатів'!$B$11 | U8: =0.2*'Бали кандидатів'!$C$6+0.2*'Бали кандидатів'!$C$7+O8*'Бали кандидатів'!$C$9+P8*'Бали кандидатів'!$C$10+Q8*'Бали кандидатів'!$C$11 | V8: =IF('Бали кандидатів'!$B$14>=300,"OK","НЕ ДОПУЩЕНО") | W8: =IF('Бали кандидатів'!$C$14>=300,"OK","НЕ ДОПУЩЕНО") | X8: =IF(AND(OR(R8="—",'Бали кандидатів'!$B$9>=R8),OR(S8="—",'Бали кандидатів'!$B$10>=S8)),"проходить","НИЖЧЕ мін. балу") | Y8: =IF(AND(OR(R8="—",'Бали кандидатів'!$C$9>=R8),OR(S8="—",'Бали кандидатів'!$C$10>=S8)),"проходить","НИЖЧЕ мін. балу") | Z8: Дослідницька пропозиція важить більше або нарівні з іспитом | AA8: ПРИВАТНИЙ ЗВО. Власний дедлайн подачі — 25.08.2026, іспити 26.08–07.09; далі лише додаткова сесія 23.09–07.10. Навчання платне | AE8: https://vstup.osvita.ua/r27/249/entrance.html | AF8: https://vstup.osvita.ua/y2026/r27/249/1649582/ | AM8: =IF(AJ8="","дані ще не вивантажені",IF('Бали кандидатів'!$B$7>=AJ8,"проходить","НЕ проходить за ЄВВ")) | AN8: =IF(AJ8="","дані ще не вивантажені",IF('Бали кандидатів'!$C$7>=AJ8,"проходить","НЕ проходить за ЄВВ"))
A9: F2 Інженерія ПЗ | B9: Міжнародний університет (Одеса) | C9: Одеса | D9: Одеська | E9: ТАК | F9: Фіксована | G9: ні | I9: Інженерія програмного забезпечення | J9: Кібербезпеки, програмної інженерії та комп'ютерних наук | K9: 1 | L9: 1 | M9: =IF(K9=0,"н/д",L9/K9) | N9: 26.08.2026 | O9: 0.6 | P9: 0 | Q9: 0 | R9: — | S9: — | T9: =0.2*'Бали кандидатів'!$B$6+0.2*'Бали кандидатів'!$B$7+O9*'Бали кандидатів'!$B$9+P9*'Бали кандидатів'!$B$10+Q9*'Бали кандидатів'!$B$11 | U9: =0.2*'Бали кандидатів'!$C$6+0.2*'Бали кандидатів'!$C$7+O9*'Бали кандидатів'!$C$9+P9*'Бали кандидатів'!$C$10+Q9*'Бали кандидатів'!$C$11 | V9: =IF('Бали кандидатів'!$B$14>=300,"OK","НЕ ДОПУЩЕНО") | W9: =IF('Бали кандидатів'!$C$14>=300,"OK","НЕ ДОПУЩЕНО") | X9: =IF(AND(OR(R9="—",'Бали кандидатів'!$B$9>=R9),OR(S9="—",'Бали кандидатів'!$B$10>=S9)),"проходить","НИЖЧЕ мін. балу") | Y9: =IF(AND(OR(R9="—",'Бали кандидатів'!$C$9>=R9),OR(S9="—",'Бали кандидатів'!$C$10>=S9)),"проходить","НИЖЧЕ мін. балу") | Z9: Тільки іспит зі спеціальності | AA9: Додаткова співбесіда для вступників з іншої спеціальності (вага 0) | AE9: https://vstup.osvita.ua/r16/353/entrance.html | AF9: https://vstup.osvita.ua/y2026/r16/353/1652604/ | AM9: =IF(AJ9="","дані ще не вивантажені",IF('Бали кандидатів'!$B$7>=AJ9,"проходить","НЕ проходить за ЄВВ")) | AN9: =IF(AJ9="","дані ще не вивантажені",IF('Бали кандидатів'!$C$7>=AJ9,"проходить","НЕ проходить за ЄВВ"))
A10: F4 Системний аналіз | B10: Харківський національний університет радіоелектроніки (ХНУРЕ) | C10: Харків | D10: Харківська | E10: ТАК | F10: Фіксована | G10: ні | I10: Системний аналіз | K10: 20 | L10: 20 | M10: =IF(K10=0,"н/д",L10/K10) | N10: 26.08.2026 | O10: 0.6 | P10: 0 | Q10: 0 | R10: 100 | S10: — | T10: =0.2*'Бали кандидатів'!$B$6+0.2*'Бали кандидатів'!$B$7+O10*'Бали кандидатів'!$B$9+P10*'Бали кандидатів'!$B$10+Q10*'Бали кандидатів'!$B$11 | U10: =0.2*'Бали кандидатів'!$C$6+0.2*'Бали кандидатів'!$C$7+O10*'Бали кандидатів'!$C$9+P10*'Бали кандидатів'!$C$10+Q10*'Бали кандидатів'!$C$11 | V10: =IF('Бали кандидатів'!$B$14>=300,"OK","НЕ ДОПУЩЕНО") | W10: =IF('Бали кандидатів'!$C$14>=300,"OK","НЕ ДОПУЩЕНО") | X10: =IF(AND(OR(R10="—",'Бали кандидатів'!$B$9>=R10),OR(S10="—",'Бали кандидатів'!$B$10>=S10)),"проходить","НИЖЧЕ мін. балу") | Y10: =IF(AND(OR(R10="—",'Бали кандидатів'!$C$9>=R10),OR(S10="—",'Бали кандидатів'!$C$10>=S10)),"проходить","НИЖЧЕ мін. балу") | Z10: Тільки іспит зі спеціальності | AA10: Ваги підтверджено зі сторінки ЗВО: іноземна 0.20, ЄВВ 0.20, іспит зі спец. 0.60, ТЗНК 0.00 — усі з мін. балом 100 | AE10: https://vstup.osvita.ua/r21/92/entrance.html | AF10: https://vstup.osvita.ua/y2026/r21/92/1653836/ | AM10: =IF(AJ10="","дані ще не вивантажені",IF('Бали кандидатів'!$B$7>=AJ10,"проходить","НЕ проходить за ЄВВ")) | AN10: =IF(AJ10="","дані ще не вивантажені",IF('Бали кандидатів'!$C$7>=AJ10,"проходить","НЕ проходить за ЄВВ"))
A11: F2 Інженерія ПЗ | B11: НУ «Львівська політехніка» | C11: Львів | D11: Львівська | E11: ТАК | F11: Фіксована | G11: ні | I11: Інженерія програмного забезпечення | J11: Інститут комп. наук та інформаційних технологій | K11: 33 | L11: 34 | M11: =IF(K11=0,"н/д",L11/K11) | N11: 26.08.2026 | O11: 0.6 | P11: 0 | Q11: 0 | R11: 110 | S11: — | T11: =0.2*'Бали кандидатів'!$B$6+0.2*'Бали кандидатів'!$B$7+O11*'Бали кандидатів'!$B$9+P11*'Бали кандидатів'!$B$10+Q11*'Бали кандидатів'!$B$11 | U11: =0.2*'Бали кандидатів'!$C$6+0.2*'Бали кандидатів'!$C$7+O11*'Бали кандидатів'!$C$9+P11*'Бали кандидатів'!$C$10+Q11*'Бали кандидатів'!$C$11 | V11: =IF('Бали кандидатів'!$B$14>=300,"OK","НЕ ДОПУЩЕНО") | W11: =IF('Бали кандидатів'!$C$14>=300,"OK","НЕ ДОПУЩЕНО") | X11: =IF(AND(OR(R11="—",'Бали кандидатів'!$B$9>=R11),OR(S11="—",'Бали кандидатів'!$B$10>=S11)),"проходить","НИЖЧЕ мін. балу") | Y11: =IF(AND(OR(R11="—",'Бали кандидатів'!$C$9>=R11),OR(S11="—",'Бали кандидатів'!$C$10>=S11)),"проходить","НИЖЧЕ мін. балу") | Z11: Тільки іспит зі спеціальності | AA11: Іспит того самого дня і години, що й F3: 09.09.2026, 14:30 | AB11: 09.09.2026 | AC11: 14:30 | AD11: I навчальний корпус, вул. Старосольських 2/4, Львів (ІКНІ) | AE11: https://vstup.osvita.ua/r14/97/entrance.html | AF11: https://vstup.osvita.ua/y2026/r14/97/1645690/ | AM11: =IF(AJ11="","дані ще не вивантажені",IF('Бали кандидатів'!$B$7>=AJ11,"проходить","НЕ проходить за ЄВВ")) | AN11: =IF(AJ11="","дані ще не вивантажені",IF('Бали кандидатів'!$C$7>=AJ11,"проходить","НЕ проходить за ЄВВ"))
A12: F3 Комп'ютерні науки | B12: Харківський національний університет ім. В. Н. Каразіна | C12: Харків | D12: Харківська | E12: ТАК | F12: Фіксована | G12: ні | I12: Комп'ютерні науки | J12: ННІ комп. наук та штучного інтелекту | K12: 21 | L12: 23 | M12: =IF(K12=0,"н/д",L12/K12) | N12: 25.08.2026 (застаріле) | O12: 0.2 | P12: 0.4 | Q12: 0 | R12: 100 | S12: 100 | T12: =0.2*'Бали кандидатів'!$B$6+0.2*'Бали кандидатів'!$B$7+O12*'Бали кандидатів'!$B$9+P12*'Бали кандидатів'!$B$10+Q12*'Бали кандидатів'!$B$11 | U12: =0.2*'Бали кандидатів'!$C$6+0.2*'Бали кандидатів'!$C$7+O12*'Бали кандидатів'!$C$9+P12*'Бали кандидатів'!$C$10+Q12*'Бали кандидатів'!$C$11 | V12: =IF('Бали кандидатів'!$B$14>=300,"OK","НЕ ДОПУЩЕНО") | W12: =IF('Бали кандидатів'!$C$14>=300,"OK","НЕ ДОПУЩЕНО") | X12: =IF(AND(OR(R12="—",'Бали кандидатів'!$B$9>=R12),OR(S12="—",'Бали кандидатів'!$B$10>=S12)),"проходить","НИЖЧЕ мін. балу") | Y12: =IF(AND(OR(R12="—",'Бали кандидатів'!$C$9>=R12),OR(S12="—",'Бали кандидатів'!$C$10>=S12)),"проходить","НИЖЧЕ мін. балу") | Z12: Дослідницька пропозиція важить більше або нарівні з іспитом | AA12: Плюс додатковий іспит зі спеціальності (вага 0) | AE12: https://vstup.osvita.ua/r21/62/entrance.html | AF12: https://vstup.osvita.ua/y2026/r21/62/1652201/ | AM12: =IF(AJ12="","дані ще не вивантажені",IF('Бали кандидатів'!$B$7>=AJ12,"проходить","НЕ проходить за ЄВВ")) | AN12: =IF(AJ12="","дані ще не вивантажені",IF('Бали кандидатів'!$C$7>=AJ12,"проходить","НЕ проходить за ЄВВ"))
A13: F2 Інженерія ПЗ | B13: Західноукраїнський національний університет | C13: Тернопіль | D13: Тернопільська | E13: ТАК | F13: Фіксована | G13: ні | I13: Інженерія програмного забезпечення | J13: Комп'ютерних інформаційних технологій | K13: 16 | L13: 18 | M13: =IF(K13=0,"н/д",L13/K13) | N13: 26.08.2026 | O13: 0.6 | P13: 0 | Q13: 0 | R13: — | S13: — | T13: =0.2*'Бали кандидатів'!$B$6+0.2*'Бали кандидатів'!$B$7+O13*'Бали кандидатів'!$B$9+P13*'Бали кандидатів'!$B$10+Q13*'Бали кандидатів'!$B$11 | U13: =0.2*'Бали кандидатів'!$C$6+0.2*'Бали кандидатів'!$C$7+O13*'Бали кандидатів'!$C$9+P13*'Бали кандидатів'!$C$10+Q13*'Бали кандидатів'!$C$11 | V13: =IF('Бали кандидатів'!$B$14>=300,"OK","НЕ ДОПУЩЕНО") | W13: =IF('Бали кандидатів'!$C$14>=300,"OK","НЕ ДОПУЩЕНО") | X13: =IF(AND(OR(R13="—",'Бали кандидатів'!$B$9>=R13),OR(S13="—",'Бали кандидатів'!$B$10>=S13)),"проходить","НИЖЧЕ мін. балу") | Y13: =IF(AND(OR(R13="—",'Бали кандидатів'!$C$9>=R13),OR(S13="—",'Бали кандидатів'!$C$10>=S13)),"проходить","НИЖЧЕ мін. балу") | Z13: Тільки іспит зі спеціальності | AA13: Додаткова співбесіда для вступників з іншої спеціальності (вага 0) | AE13: https://vstup.osvita.ua/r20/171/entrance.html | AF13: https://vstup.osvita.ua/y2026/r20/171/1652653/ | AM13: =IF(AJ13="","дані ще не вивантажені",IF('Бали кандидатів'!$B$7>=AJ13,"проходить","НЕ проходить за ЄВВ")) | AN13: =IF(AJ13="","дані ще не вивантажені",IF('Бали кандидатів'!$C$7>=AJ13,"проходить","НЕ проходить за ЄВВ"))
A14: F3 Комп'ютерні науки | B14: Український державний університет науки і технологій | C14: Дніпро | D14: Дніпропетровська | E14: ТАК | F14: Фіксована | G14: ні | I14: Комп'ютерні науки і технології | J14: Інформаційних технологій та механічної інженерії | K14: 6 | L14: 7 | M14: =IF(K14=0,"н/д",L14/K14) | N14: 25.08.2026 (застаріле) | O14: 0.6 | P14: 0 | Q14: 0 | R14: — | S14: — | T14: =0.2*'Бали кандидатів'!$B$6+0.2*'Бали кандидатів'!$B$7+O14*'Бали кандидатів'!$B$9+P14*'Бали кандидатів'!$B$10+Q14*'Бали кандидатів'!$B$11 | U14: =0.2*'Бали кандидатів'!$C$6+0.2*'Бали кандидатів'!$C$7+O14*'Бали кандидатів'!$C$9+P14*'Бали кандидатів'!$C$10+Q14*'Бали кандидатів'!$C$11 | V14: =IF('Бали кандидатів'!$B$14>=300,"OK","НЕ ДОПУЩЕНО") | W14: =IF('Бали кандидатів'!$C$14>=300,"OK","НЕ ДОПУЩЕНО") | X14: =IF(AND(OR(R14="—",'Бали кандидатів'!$B$9>=R14),OR(S14="—",'Бали кандидатів'!$B$10>=S14)),"проходить","НИЖЧЕ мін. балу") | Y14: =IF(AND(OR(R14="—",'Бали кандидатів'!$C$9>=R14),OR(S14="—",'Бали кандидатів'!$C$10>=S14)),"проходить","НИЖЧЕ мін. балу") | Z14: Тільки іспит зі спеціальності | AE14: https://vstup.osvita.ua/r5/6507/entrance.html | AF14: https://vstup.osvita.ua/y2026/r5/6507/1673562/ | AM14: =IF(AJ14="","дані ще не вивантажені",IF('Бали кандидатів'!$B$7>=AJ14,"проходить","НЕ проходить за ЄВВ")) | AN14: =IF(AJ14="","дані ще не вивантажені",IF('Бали кандидатів'!$C$7>=AJ14,"проходить","НЕ проходить за ЄВВ"))
A15: F3 Комп'ютерні науки | B15: Черкаський національний університет ім. Б. Хмельницького | C15: Черкаси | D15: Черкаська | E15: ТАК | F15: Фіксована | G15: ні | I15: Комп'ютерні науки | J15: Обчислювальної техніки, інтел. та управляючих систем | K15: 5 | L15: 6 | M15: =IF(K15=0,"н/д",L15/K15) | N15: 26.08.2026 | O15: 0.6 | P15: 0 | Q15: 0 | R15: — | S15: — | T15: =0.2*'Бали кандидатів'!$B$6+0.2*'Бали кандидатів'!$B$7+O15*'Бали кандидатів'!$B$9+P15*'Бали кандидатів'!$B$10+Q15*'Бали кандидатів'!$B$11 | U15: =0.2*'Бали кандидатів'!$C$6+0.2*'Бали кандидатів'!$C$7+O15*'Бали кандидатів'!$C$9+P15*'Бали кандидатів'!$C$10+Q15*'Бали кандидатів'!$C$11 | V15: =IF('Бали кандидатів'!$B$14>=300,"OK","НЕ ДОПУЩЕНО") | W15: =IF('Бали кандидатів'!$C$14>=300,"OK","НЕ ДОПУЩЕНО") | X15: =IF(AND(OR(R15="—",'Бали кандидатів'!$B$9>=R15),OR(S15="—",'Бали кандидатів'!$B$10>=S15)),"проходить","НИЖЧЕ мін. балу") | Y15: =IF(AND(OR(R15="—",'Бали кандидатів'!$C$9>=R15),OR(S15="—",'Бали кандидатів'!$C$10>=S15)),"проходить","НИЖЧЕ мін. балу") | Z15: Тільки іспит зі спеціальності | AA15: Додаткова співбесіда для вступників з іншої спеціальності (вага 0) | AE15: https://vstup.osvita.ua/r24/101/entrance.html | AF15: https://vstup.osvita.ua/y2026/r24/101/1653528/ | AM15: =IF(AJ15="","дані ще не вивантажені",IF('Бали кандидатів'!$B$7>=AJ15,"проходить","НЕ проходить за ЄВВ")) | AN15: =IF(AJ15="","дані ще не вивантажені",IF('Бали кандидатів'!$C$7>=AJ15,"проходить","НЕ проходить за ЄВВ"))
A16: F3 Комп'ютерні науки | B16: Одеський національний морський університет | C16: Одеса | D16: Одеська | E16: ТАК | F16: Фіксована | G16: ні | I16: Комп'ютерні науки | J16: Аспірантура | K16: 5 | L16: 6 | M16: =IF(K16=0,"н/д",L16/K16) | N16: 26.08.2026 | O16: 0.6 | P16: 0 | Q16: 0 | R16: 100 | S16: — | T16: =0.2*'Бали кандидатів'!$B$6+0.2*'Бали кандидатів'!$B$7+O16*'Бали кандидатів'!$B$9+P16*'Бали кандидатів'!$B$10+Q16*'Бали кандидатів'!$B$11 | U16: =0.2*'Бали кандидатів'!$C$6+0.2*'Бали кандидатів'!$C$7+O16*'Бали кандидатів'!$C$9+P16*'Бали кандидатів'!$C$10+Q16*'Бали кандидатів'!$C$11 | V16: =IF('Бали кандидатів'!$B$14>=300,"OK","НЕ ДОПУЩЕНО") | W16: =IF('Бали кандидатів'!$C$14>=300,"OK","НЕ ДОПУЩЕНО") | X16: =IF(AND(OR(R16="—",'Бали кандидатів'!$B$9>=R16),OR(S16="—",'Бали кандидатів'!$B$10>=S16)),"проходить","НИЖЧЕ мін. балу") | Y16: =IF(AND(OR(R16="—",'Бали кандидатів'!$C$9>=R16),OR(S16="—",'Бали кандидатів'!$C$10>=S16)),"проходить","НИЖЧЕ мін. балу") | Z16: Тільки іспит зі спеціальності | AE16: https://vstup.osvita.ua/r16/220/entrance.html | AF16: https://vstup.osvita.ua/y2026/r16/220/1647741/ | AM16: =IF(AJ16="","дані ще не вивантажені",IF('Бали кандидатів'!$B$7>=AJ16,"проходить","НЕ проходить за ЄВВ")) | AN16: =IF(AJ16="","дані ще не вивантажені",IF('Бали кандидатів'!$C$7>=AJ16,"проходить","НЕ проходить за ЄВВ"))
A17: F2 Інженерія ПЗ | B17: Черкаський національний університет ім. Б. Хмельницького | C17: Черкаси | D17: Черкаська | E17: ТАК | F17: Фіксована | G17: ні | I17: Інженерія програмного забезпечення | J17: Обчислювальної техніки, інтел. та управляючих систем | K17: 5 | L17: 6 | M17: =IF(K17=0,"н/д",L17/K17) | N17: 26.08.2026 | O17: 0.6 | P17: 0 | Q17: 0 | R17: — | S17: — | T17: =0.2*'Бали кандидатів'!$B$6+0.2*'Бали кандидатів'!$B$7+O17*'Бали кандидатів'!$B$9+P17*'Бали кандидатів'!$B$10+Q17*'Бали кандидатів'!$B$11 | U17: =0.2*'Бали кандидатів'!$C$6+0.2*'Бали кандидатів'!$C$7+O17*'Бали кандидатів'!$C$9+P17*'Бали кандидатів'!$C$10+Q17*'Бали кандидатів'!$C$11 | V17: =IF('Бали кандидатів'!$B$14>=300,"OK","НЕ ДОПУЩЕНО") | W17: =IF('Бали кандидатів'!$C$14>=300,"OK","НЕ ДОПУЩЕНО") | X17: =IF(AND(OR(R17="—",'Бали кандидатів'!$B$9>=R17),OR(S17="—",'Бали кандидатів'!$B$10>=S17)),"проходить","НИЖЧЕ мін. балу") | Y17: =IF(AND(OR(R17="—",'Бали кандидатів'!$C$9>=R17),OR(S17="—",'Бали кандидатів'!$C$10>=S17)),"проходить","НИЖЧЕ мін. балу") | Z17: Тільки іспит зі спеціальності | AA17: Додаткова співбесіда для вступників з іншої спеціальності (вага 0) | AE17: https://vstup.osvita.ua/r24/101/entrance.html | AF17: https://vstup.osvita.ua/y2026/r24/101/1653544/ | AM17: =IF(AJ17="","дані ще не вивантажені",IF('Бали кандидатів'!$B$7>=AJ17,"проходить","НЕ проходить за ЄВВ")) | AN17: =IF(AJ17="","дані ще не вивантажені",IF('Бали кандидатів'!$C$7>=AJ17,"проходить","НЕ проходить за ЄВВ"))
A18: F3 Комп'ютерні науки | B18: Херсонський національний технічний університет | C18: Херсон | D18: Херсонська | E18: ТАК | F18: Фіксована | G18: ТАК | H18: ПЕРЕМІЩЕНИЙ (2022). УВАГА: у ЄДЕБО регіон Херсонська обл., але за іншими джерелами фактично працює у Хмельницькому — уточнити у ЗВО | I18: Комп'ютерні науки | J18: Інформаційних технологій та дизайну | K18: 14 | L18: 17 | M18: =IF(K18=0,"н/д",L18/K18) | N18: 25.08.2026 (застаріле) | O18: 0.4 | P18: 0.2 | Q18: 0 | R18: — | S18: 100 | T18: =0.2*'Бали кандидатів'!$B$6+0.2*'Бали кандидатів'!$B$7+O18*'Бали кандидатів'!$B$9+P18*'Бали кандидатів'!$B$10+Q18*'Бали кандидатів'!$B$11 | U18: =0.2*'Бали кандидатів'!$C$6+0.2*'Бали кандидатів'!$C$7+O18*'Бали кандидатів'!$C$9+P18*'Бали кандидатів'!$C$10+Q18*'Бали кандидатів'!$C$11 | V18: =IF('Бали кандидатів'!$B$14>=300,"OK","НЕ ДОПУЩЕНО") | W18: =IF('Бали кандидатів'!$C$14>=300,"OK","НЕ ДОПУЩЕНО") | X18: =IF(AND(OR(R18="—",'Бали кандидатів'!$B$9>=R18),OR(S18="—",'Бали кандидатів'!$B$10>=S18)),"проходить","НИЖЧЕ мін. балу") | Y18: =IF(AND(OR(R18="—",'Бали кандидатів'!$C$9>=R18),OR(S18="—",'Бали кандидатів'!$C$10>=S18)),"проходить","НИЖЧЕ мін. балу") | Z18: Іспит + дослідницька пропозиція | AA18: Плюс додаткова співбесіда зі спеціальності (вага 0) | AE18: https://vstup.osvita.ua/r22/86/entrance.html | AF18: https://vstup.osvita.ua/y2026/r22/86/1648125/ | AM18: =IF(AJ18="","дані ще не вивантажені",IF('Бали кандидатів'!$B$7>=AJ18,"проходить","НЕ проходить за ЄВВ")) | AN18: =IF(AJ18="","дані ще не вивантажені",IF('Бали кандидатів'!$C$7>=AJ18,"проходить","НЕ проходить за ЄВВ"))
A19: F3 Комп'ютерні науки | B19: Інститут проблем математичних машин і систем НАНУ | C19: Київ | D19: Київ | E19: ТАК | F19: Фіксована | G19: ні | I19: Комп'ютерні науки | K19: 6 | L19: 8 | M19: =IF(K19=0,"н/д",L19/K19) | N19: 25.08.2026 (застаріле) | O19: 0.6 | P19: 0 | Q19: 0 | R19: — | S19: — | T19: =0.2*'Бали кандидатів'!$B$6+0.2*'Бали кандидатів'!$B$7+O19*'Бали кандидатів'!$B$9+P19*'Бали кандидатів'!$B$10+Q19*'Бали кандидатів'!$B$11 | U19: =0.2*'Бали кандидатів'!$C$6+0.2*'Бали кандидатів'!$C$7+O19*'Бали кандидатів'!$C$9+P19*'Бали кандидатів'!$C$10+Q19*'Бали кандидатів'!$C$11 | V19: =IF('Бали кандидатів'!$B$14>=300,"OK","НЕ ДОПУЩЕНО") | W19: =IF('Бали кандидатів'!$C$14>=300,"OK","НЕ ДОПУЩЕНО") | X19: =IF(AND(OR(R19="—",'Бали кандидатів'!$B$9>=R19),OR(S19="—",'Бали кандидатів'!$B$10>=S19)),"проходить","НИЖЧЕ мін. балу") | Y19: =IF(AND(OR(R19="—",'Бали кандидатів'!$C$9>=R19),OR(S19="—",'Бали кандидатів'!$C$10>=S19)),"проходить","НИЖЧЕ мін. балу") | Z19: Тільки іспит зі спеціальності | AE19: https://vstup.osvita.ua/r27/3582/entrance.html | AF19: https://vstup.osvita.ua/y2026/r27/3582/1649593/ | AM19: =IF(AJ19="","дані ще не вивантажені",IF('Бали кандидатів'!$B$7>=AJ19,"проходить","НЕ проходить за ЄВВ")) | AN19: =IF(AJ19="","дані ще не вивантажені",IF('Бали кандидатів'!$C$7>=AJ19,"проходить","НЕ проходить за ЄВВ"))
A20: F3 Комп'ютерні науки | B20: Ужгородський національний університет | C20: Ужгород | D20: Закарпатська | E20: ТАК | F20: Фіксована | G20: ні | I20: Комп'ютерні науки | J20: Факультет інформаційних технологій | K20: 5 | L20: 7 | M20: =IF(K20=0,"н/д",L20/K20) | N20: 26.08.2026 | O20: 0.4 | P20: 0.2 | Q20: 0 | R20: 100 | S20: 100 | T20: =0.2*'Бали кандидатів'!$B$6+0.2*'Бали кандидатів'!$B$7+O20*'Бали кандидатів'!$B$9+P20*'Бали кандидатів'!$B$10+Q20*'Бали кандидатів'!$B$11 | U20: =0.2*'Бали кандидатів'!$C$6+0.2*'Бали кандидатів'!$C$7+O20*'Бали кандидатів'!$C$9+P20*'Бали кандидатів'!$C$10+Q20*'Бали кандидатів'!$C$11 | V20: =IF('Бали кандидатів'!$B$14>=300,"OK","НЕ ДОПУЩЕНО") | W20: =IF('Бали кандидатів'!$C$14>=300,"OK","НЕ ДОПУЩЕНО") | X20: =IF(AND(OR(R20="—",'Бали кандидатів'!$B$9>=R20),OR(S20="—",'Бали кандидатів'!$B$10>=S20)),"проходить","НИЖЧЕ мін. балу") | Y20: =IF(AND(OR(R20="—",'Бали кандидатів'!$C$9>=R20),OR(S20="—",'Бали кандидатів'!$C$10>=S20)),"проходить","НИЖЧЕ мін. балу") | Z20: Іспит + дослідницька пропозиція | AE20: https://vstup.osvita.ua/r8/207/entrance.html | AF20: https://vstup.osvita.ua/y2026/r8/207/1643044/ | AM20: =IF(AJ20="","дані ще не вивантажені",IF('Бали кандидатів'!$B$7>=AJ20,"проходить","НЕ проходить за ЄВВ")) | AN20: =IF(AJ20="","дані ще не вивантажені",IF('Бали кандидатів'!$C$7>=AJ20,"проходить","НЕ проходить за ЄВВ"))
A21: F3 Комп'ютерні науки | B21: Одеський національний університет ім. І. І. Мечникова | C21: Одеса | D21: Одеська | E21: ТАК | F21: Фіксована | G21: ні | I21: Комп'ютерні науки | J21: Відділ аспірантури та докторантури | K21: 15 | L21: 22 | M21: =IF(K21=0,"н/д",L21/K21) | N21: 26.08.2026 | O21: 0.6 | P21: 0 | Q21: 0 | R21: 100 | S21: — | T21: =0.2*'Бали кандидатів'!$B$6+0.2*'Бали кандидатів'!$B$7+O21*'Бали кандидатів'!$B$9+P21*'Бали кандидатів'!$B$10+Q21*'Бали кандидатів'!$B$11 | U21: =0.2*'Бали кандидатів'!$C$6+0.2*'Бали кандидатів'!$C$7+O21*'Бали кандидатів'!$C$9+P21*'Бали кандидатів'!$C$10+Q21*'Бали кандидатів'!$C$11 | V21: =IF('Бали кандидатів'!$B$14>=300,"OK","НЕ ДОПУЩЕНО") | W21: =IF('Бали кандидатів'!$C$14>=300,"OK","НЕ ДОПУЩЕНО") | X21: =IF(AND(OR(R21="—",'Бали кандидатів'!$B$9>=R21),OR(S21="—",'Бали кандидатів'!$B$10>=S21)),"проходить","НИЖЧЕ мін. балу") | Y21: =IF(AND(OR(R21="—",'Бали кандидатів'!$C$9>=R21),OR(S21="—",'Бали кандидатів'!$C$10>=S21)),"проходить","НИЖЧЕ мін. балу") | Z21: Тільки іспит зі спеціальності | AE21: https://vstup.osvita.ua/r16/28/entrance.html | AF21: https://vstup.osvita.ua/y2026/r16/28/1648414/ | AM21: =IF(AJ21="","дані ще не вивантажені",IF('Бали кандидатів'!$B$7>=AJ21,"проходить","НЕ проходить за ЄВВ")) | AN21: =IF(AJ21="","дані ще не вивантажені",IF('Бали кандидатів'!$C$7>=AJ21,"проходить","НЕ проходить за ЄВВ"))
A22: F4 Системний аналіз | B22: НУ «Одеська політехніка» | C22: Одеса | D22: Одеська | E22: ТАК | F22: Фіксована | G22: ні | I22: Системний аналіз та наука про дані | J22: Відділ аспірантури і докторантури | K22: 4 | L22: 6 | M22: =IF(K22=0,"н/д",L22/K22) | N22: 26.08.2026 | O22: ? | P22: ? | Q22: ? | R22: ? | S22: ? | T22: ваги невідомі | U22: ваги невідомі | V22: =IF('Бали кандидатів'!$B$14>=300,"OK","НЕ ДОПУЩЕНО") | W22: =IF('Бали кандидатів'!$C$14>=300,"OK","НЕ ДОПУЩЕНО") | X22: — | Y22: — | Z22: ваги не зчитані — уточнити на сторінці пропозиції | AA22: Складові конкурсного бала у вихідних даних відсутні — відкрити «Детальніше» на сторінці ЗВО | AE22: https://vstup.osvita.ua/r16/5754/entrance.html | AF22: https://vstup.osvita.ua/r16/5754/ | AM22: =IF(AJ22="","дані ще не вивантажені",IF('Бали кандидатів'!$B$7>=AJ22,"проходить","НЕ проходить за ЄВВ")) | AN22: =IF(AJ22="","дані ще не вивантажені",IF('Бали кандидатів'!$C$7>=AJ22,"проходить","НЕ проходить за ЄВВ"))
A23: F2 Інженерія ПЗ | B23: Черкаський державний технологічний університет | C23: Черкаси | D23: Черкаська | E23: ТАК | F23: Фіксована | G23: ні | I23: Інженерія програмного забезпечення | J23: Інформаційних технологій і систем | K23: 5 | L23: 8 | M23: =IF(K23=0,"н/д",L23/K23) | N23: 26.08.2026 | O23: 0.6 | P23: 0 | Q23: 0 | R23: — | S23: — | T23: =0.2*'Бали кандидатів'!$B$6+0.2*'Бали кандидатів'!$B$7+O23*'Бали кандидатів'!$B$9+P23*'Бали кандидатів'!$B$10+Q23*'Бали кандидатів'!$B$11 | U23: =0.2*'Бали кандидатів'!$C$6+0.2*'Бали кандидатів'!$C$7+O23*'Бали кандидатів'!$C$9+P23*'Бали кандидатів'!$C$10+Q23*'Бали кандидатів'!$C$11 | V23: =IF('Бали кандидатів'!$B$14>=300,"OK","НЕ ДОПУЩЕНО") | W23: =IF('Бали кандидатів'!$C$14>=300,"OK","НЕ ДОПУЩЕНО") | X23: =IF(AND(OR(R23="—",'Бали кандидатів'!$B$9>=R23),OR(S23="—",'Бали кандидатів'!$B$10>=S23)),"проходить","НИЖЧЕ мін. балу") | Y23: =IF(AND(OR(R23="—",'Бали кандидатів'!$C$9>=R23),OR(S23="—",'Бали кандидатів'!$C$10>=S23)),"проходить","НИЖЧЕ мін. балу") | Z23: Тільки іспит зі спеціальності | AE23: https://vstup.osvita.ua/r24/248/entrance.html | AF23: https://vstup.osvita.ua/y2026/r24/248/1648421/ | AM23: =IF(AJ23="","дані ще не вивантажені",IF('Бали кандидатів'!$B$7>=AJ23,"проходить","НЕ проходить за ЄВВ")) | AN23: =IF(AJ23="","дані ще не вивантажені",IF('Бали кандидатів'!$C$7>=AJ23,"проходить","НЕ проходить за ЄВВ"))
A24: F2 Інженерія ПЗ | B24: Тернопільський національний технічний університет ім. І. Пулюя | C24: Тернопіль | D24: Тернопільська | E24: ТАК | F24: Фіксована | G24: ні | I24: Інженерія програмного забезпечення | K24: 8 | L24: 13 | M24: =IF(K24=0,"н/д",L24/K24) | N24: 26.08.2026 | O24: 0.6 | P24: 0 | Q24: 0 | R24: 100 | S24: — | T24: =0.2*'Бали кандидатів'!$B$6+0.2*'Бали кандидатів'!$B$7+O24*'Бали кандидатів'!$B$9+P24*'Бали кандидатів'!$B$10+Q24*'Бали кандидатів'!$B$11 | U24: =0.2*'Бали кандидатів'!$C$6+0.2*'Бали кандидатів'!$C$7+O24*'Бали кандидатів'!$C$9+P24*'Бали кандидатів'!$C$10+Q24*'Бали кандидатів'!$C$11 | V24: =IF('Бали кандидатів'!$B$14>=300,"OK","НЕ ДОПУЩЕНО") | W24: =IF('Бали кандидатів'!$C$14>=300,"OK","НЕ ДОПУЩЕНО") | X24: =IF(AND(OR(R24="—",'Бали кандидатів'!$B$9>=R24),OR(S24="—",'Бали кандидатів'!$B$10>=S24)),"проходить","НИЖЧЕ мін. балу") | Y24: =IF(AND(OR(R24="—",'Бали кандидатів'!$C$9>=R24),OR(S24="—",'Бали кандидатів'!$C$10>=S24)),"проходить","НИЖЧЕ мін. балу") | Z24: Тільки іспит зі спеціальності | AE24: https://vstup.osvita.ua/r20/166/entrance.html | AF24: https://vstup.osvita.ua/y2026/r20/166/1644708/ | AM24: =IF(AJ24="","дані ще не вивантажені",IF('Бали кандидатів'!$B$7>=AJ24,"проходить","НЕ проходить за ЄВВ")) | AN24: =IF(AJ24="","дані ще не вивантажені",IF('Бали кандидатів'!$C$7>=AJ24,"проходить","НЕ проходить за ЄВВ"))
A25: F3 Комп'ютерні науки | B25: Західноукраїнський національний університет | C25: Тернопіль | D25: Тернопільська | E25: ТАК | F25: Фіксована | G25: ні | I25: Комп'ютерні науки | J25: Комп'ютерних інформаційних технологій | K25: 11 | L25: 18 | M25: =IF(K25=0,"н/д",L25/K25) | N25: 26.08.2026 | O25: 0.6 | P25: 0 | Q25: 0 | R25: — | S25: — | T25: =0.2*'Бали кандидатів'!$B$6+0.2*'Бали кандидатів'!$B$7+O25*'Бали кандидатів'!$B$9+P25*'Бали кандидатів'!$B$10+Q25*'Бали кандидатів'!$B$11 | U25: =0.2*'Бали кандидатів'!$C$6+0.2*'Бали кандидатів'!$C$7+O25*'Бали кандидатів'!$C$9+P25*'Бали кандидатів'!$C$10+Q25*'Бали кандидатів'!$C$11 | V25: =IF('Бали кандидатів'!$B$14>=300,"OK","НЕ ДОПУЩЕНО") | W25: =IF('Бали кандидатів'!$C$14>=300,"OK","НЕ ДОПУЩЕНО") | X25: =IF(AND(OR(R25="—",'Бали кандидатів'!$B$9>=R25),OR(S25="—",'Бали кандидатів'!$B$10>=S25)),"проходить","НИЖЧЕ мін. балу") | Y25: =IF(AND(OR(R25="—",'Бали кандидатів'!$C$9>=R25),OR(S25="—",'Бали кандидатів'!$C$10>=S25)),"проходить","НИЖЧЕ мін. балу") | Z25: Тільки іспит зі спеціальності | AA25: Додаткова співбесіда для вступників з іншої спеціальності (вага 0) | AE25: https://vstup.osvita.ua/r20/171/entrance.html | AF25: https://vstup.osvita.ua/y2026/r20/171/1652658/ | AM25: =IF(AJ25="","дані ще не вивантажені",IF('Бали кандидатів'!$B$7>=AJ25,"проходить","НЕ проходить за ЄВВ")) | AN25: =IF(AJ25="","дані ще не вивантажені",IF('Бали кандидатів'!$C$7>=AJ25,"проходить","НЕ проходить за ЄВВ"))
A26: F3 Комп'ютерні науки | B26: Харківський авіаційний інститут (ХАІ) | C26: Харків | D26: Харківська | E26: ТАК | F26: Фіксована | G26: ні | I26: Інформаційні технології | J26: Радіоелектроніки, комп. систем та інфокомунікацій | K26: 3 | L26: 5 | M26: =IF(K26=0,"н/д",L26/K26) | N26: 26.08.2026 | O26: 0.6 | P26: 0 | Q26: 0 | R26: — | S26: — | T26: =0.2*'Бали кандидатів'!$B$6+0.2*'Бали кандидатів'!$B$7+O26*'Бали кандидатів'!$B$9+P26*'Бали кандидатів'!$B$10+Q26*'Бали кандидатів'!$B$11 | U26: =0.2*'Бали кандидатів'!$C$6+0.2*'Бали кандидатів'!$C$7+O26*'Бали кандидатів'!$C$9+P26*'Бали кандидатів'!$C$10+Q26*'Бали кандидатів'!$C$11 | V26: =IF('Бали кандидатів'!$B$14>=300,"OK","НЕ ДОПУЩЕНО") | W26: =IF('Бали кандидатів'!$C$14>=300,"OK","НЕ ДОПУЩЕНО") | X26: =IF(AND(OR(R26="—",'Бали кандидатів'!$B$9>=R26),OR(S26="—",'Бали кандидатів'!$B$10>=S26)),"проходить","НИЖЧЕ мін. балу") | Y26: =IF(AND(OR(R26="—",'Бали кандидатів'!$C$9>=R26),OR(S26="—",'Бали кандидатів'!$C$10>=S26)),"проходить","НИЖЧЕ мін. балу") | Z26: Тільки іспит зі спеціальності | AE26: https://vstup.osvita.ua/r21/34/entrance.html | AF26: https://vstup.osvita.ua/y2026/r21/34/1644836/ | AM26: =IF(AJ26="","дані ще не вивантажені",IF('Бали кандидатів'!$B$7>=AJ26,"проходить","НЕ проходить за ЄВВ")) | AN26: =IF(AJ26="","дані ще не вивантажені",IF('Бали кандидатів'!$C$7>=AJ26,"проходить","НЕ проходить за ЄВВ"))
A27: F3 Комп'ютерні науки | B27: Харківський національний економічний університет ім. С. Кузнеця | C27: Харків | D27: Харківська | E27: ТАК | F27: Фіксована | G27: ні | I27: Комп'ютерні науки | J27: Відділ аспірантури і докторантури | K27: 13 | L27: 22 | M27: =IF(K27=0,"н/д",L27/K27) | N27: 26.08.2026 | O27: 0.6 | P27: 0 | Q27: 0 | R27: 100 | S27: — | T27: =0.2*'Бали кандидатів'!$B$6+0.2*'Бали кандидатів'!$B$7+O27*'Бали кандидатів'!$B$9+P27*'Бали кандидатів'!$B$10+Q27*'Бали кандидатів'!$B$11 | U27: =0.2*'Бали кандидатів'!$C$6+0.2*'Бали кандидатів'!$C$7+O27*'Бали кандидатів'!$C$9+P27*'Бали кандидатів'!$C$10+Q27*'Бали кандидатів'!$C$11 | V27: =IF('Бали кандидатів'!$B$14>=300,"OK","НЕ ДОПУЩЕНО") | W27: =IF('Бали кандидатів'!$C$14>=300,"OK","НЕ ДОПУЩЕНО") | X27: =IF(AND(OR(R27="—",'Бали кандидатів'!$B$9>=R27),OR(S27="—",'Бали кандидатів'!$B$10>=S27)),"проходить","НИЖЧЕ мін. балу") | Y27: =IF(AND(OR(R27="—",'Бали кандидатів'!$C$9>=R27),OR(S27="—",'Бали кандидатів'!$C$10>=S27)),"проходить","НИЖЧЕ мін. балу") | Z27: Тільки іспит зі спеціальності | AE27: https://vstup.osvita.ua/r21/227/entrance.html | AF27: https://vstup.osvita.ua/y2026/r21/227/1649303/ | AM27: =IF(AJ27="","дані ще не вивантажені",IF('Бали кандидатів'!$B$7>=AJ27,"проходить","НЕ проходить за ЄВВ")) | AN27: =IF(AJ27="","дані ще не вивантажені",IF('Бали кандидатів'!$C$7>=AJ27,"проходить","НЕ проходить за ЄВВ"))
A28: F3 Комп'ютерні науки | B28: Національний університет водного господарства та природокористування | C28: Рівне | D28: Рівненська | E28: ТАК | F28: Фіксована | G28: ні | I28: Комп'ютерні науки | K28: 10 | L28: 17 | M28: =IF(K28=0,"н/д",L28/K28) | N28: 26.08.2026 | O28: 0.6 | P28: 0 | Q28: 0 | R28: — | S28: — | T28: =0.2*'Бали кандидатів'!$B$6+0.2*'Бали кандидатів'!$B$7+O28*'Бали кандидатів'!$B$9+P28*'Бали кандидатів'!$B$10+Q28*'Бали кандидатів'!$B$11 | U28: =0.2*'Бали кандидатів'!$C$6+0.2*'Бали кандидатів'!$C$7+O28*'Бали кандидатів'!$C$9+P28*'Бали кандидатів'!$C$10+Q28*'Бали кандидатів'!$C$11 | V28: =IF('Бали кандидатів'!$B$14>=300,"OK","НЕ ДОПУЩЕНО") | W28: =IF('Бали кандидатів'!$C$14>=300,"OK","НЕ ДОПУЩЕНО") | X28: =IF(AND(OR(R28="—",'Бали кандидатів'!$B$9>=R28),OR(S28="—",'Бали кандидатів'!$B$10>=S28)),"проходить","НИЖЧЕ мін. балу") | Y28: =IF(AND(OR(R28="—",'Бали кандидатів'!$C$9>=R28),OR(S28="—",'Бали кандидатів'!$C$10>=S28)),"проходить","НИЖЧЕ мін. балу") | Z28: Тільки іспит зі спеціальності | AE28: https://vstup.osvita.ua/r18/9/entrance.html | AF28: https://vstup.osvita.ua/y2026/r18/9/1650315/ | AM28: =IF(AJ28="","дані ще не вивантажені",IF('Бали кандидатів'!$B$7>=AJ28,"проходить","НЕ проходить за ЄВВ")) | AN28: =IF(AJ28="","дані ще не вивантажені",IF('Бали кандидатів'!$C$7>=AJ28,"проходить","НЕ проходить за ЄВВ"))
A29: F4 Системний аналіз | B29: Київський національний університет ім. Т. Шевченка | C29: Київ | D29: Київ | E29: ТАК | F29: Фіксована | G29: ні | I29: Системний аналіз | J29: Комп'ютерних наук та кібернетики | K29: 7 | L29: 12 | M29: =IF(K29=0,"н/д",L29/K29) | N29: 26.08.2026 | O29: ? | P29: ? | Q29: ? | R29: ? | S29: ? | T29: ваги невідомі | U29: ваги невідомі | V29: =IF('Бали кандидатів'!$B$14>=300,"OK","НЕ ДОПУЩЕНО") | W29: =IF('Бали кандидатів'!$C$14>=300,"OK","НЕ ДОПУЩЕНО") | X29: — | Y29: — | Z29: ваги не зчитані — уточнити на сторінці пропозиції | AA29: Складові конкурсного бала у вихідних даних відсутні — відкрити «Детальніше» на сторінці ЗВО | AE29: https://vstup.osvita.ua/r27/41/entrance.html | AF29: https://vstup.osvita.ua/r27/41/ | AM29: =IF(AJ29="","дані ще не вивантажені",IF('Бали кандидатів'!$B$7>=AJ29,"проходить","НЕ проходить за ЄВВ")) | AN29: =IF(AJ29="","дані ще не вивантажені",IF('Бали кандидатів'!$C$7>=AJ29,"проходить","НЕ проходить за ЄВВ"))
A30: F3 Комп'ютерні науки | B30: Житомирський державний університет ім. І. Франка | C30: Житомир | D30: Житомирська | E30: ТАК | F30: Фіксована | G30: ні | I30: Комп'ютерні науки | J30: Фізико-математичний | K30: 4 | L30: 7 | M30: =IF(K30=0,"н/д",L30/K30) | N30: 26.08.2026 | O30: 0.4 | P30: 0 | Q30: 0.2 | R30: 100 | S30: — | T30: =0.2*'Бали кандидатів'!$B$6+0.2*'Бали кандидатів'!$B$7+O30*'Бали кандидатів'!$B$9+P30*'Бали кандидатів'!$B$10+Q30*'Бали кандидатів'!$B$11 | U30: =0.2*'Бали кандидатів'!$C$6+0.2*'Бали кандидатів'!$C$7+O30*'Бали кандидатів'!$C$9+P30*'Бали кандидатів'!$C$10+Q30*'Бали кандидатів'!$C$11 | V30: =IF('Бали кандидатів'!$B$14>=300,"OK","НЕ ДОПУЩЕНО") | W30: =IF('Бали кандидатів'!$C$14>=300,"OK","НЕ ДОПУЩЕНО") | X30: =IF(AND(OR(R30="—",'Бали кандидатів'!$B$9>=R30),OR(S30="—",'Бали кандидатів'!$B$10>=S30)),"проходить","НИЖЧЕ мін. балу") | Y30: =IF(AND(OR(R30="—",'Бали кандидатів'!$C$9>=R30),OR(S30="—",'Бали кандидатів'!$C$10>=S30)),"проходить","НИЖЧЕ мін. балу") | Z30: Тільки іспит зі спеціальності | AA30: Окремий іспит з ФІЛОСОФІЇ, вага 0.20, мін. бал 100 | AE30: https://vstup.osvita.ua/r7/109/entrance.html | AF30: https://vstup.osvita.ua/y2026/r7/109/1645952/ | AM30: =IF(AJ30="","дані ще не вивантажені",IF('Бали кандидатів'!$B$7>=AJ30,"проходить","НЕ проходить за ЄВВ")) | AN30: =IF(AJ30="","дані ще не вивантажені",IF('Бали кандидатів'!$C$7>=AJ30,"проходить","НЕ проходить за ЄВВ"))
A31: F3 Комп'ютерні науки | B31: Український державний університет науки і технологій | C31: Дніпро | D31: Дніпропетровська | E31: ТАК | F31: Фіксована | G31: ні | I31: Комп'ютерні науки і технології | J31: Комп'ютерні технології і системи | K31: 8 | L31: 14 | M31: =IF(K31=0,"н/д",L31/K31) | N31: 25.08.2026 (застаріле) | O31: 0.6 | P31: 0 | Q31: 0 | R31: — | S31: — | T31: =0.2*'Бали кандидатів'!$B$6+0.2*'Бали кандидатів'!$B$7+O31*'Бали кандидатів'!$B$9+P31*'Бали кандидатів'!$B$10+Q31*'Бали кандидатів'!$B$11 | U31: =0.2*'Бали кандидатів'!$C$6+0.2*'Бали кандидатів'!$C$7+O31*'Бали кандидатів'!$C$9+P31*'Бали кандидатів'!$C$10+Q31*'Бали кандидатів'!$C$11 | V31: =IF('Бали кандидатів'!$B$14>=300,"OK","НЕ ДОПУЩЕНО") | W31: =IF('Бали кандидатів'!$C$14>=300,"OK","НЕ ДОПУЩЕНО") | X31: =IF(AND(OR(R31="—",'Бали кандидатів'!$B$9>=R31),OR(S31="—",'Бали кандидатів'!$B$10>=S31)),"проходить","НИЖЧЕ мін. балу") | Y31: =IF(AND(OR(R31="—",'Бали кандидатів'!$C$9>=R31),OR(S31="—",'Бали кандидатів'!$C$10>=S31)),"проходить","НИЖЧЕ мін. балу") | Z31: Тільки іспит зі спеціальності | AE31: https://vstup.osvita.ua/r5/6507/entrance.html | AF31: https://vstup.osvita.ua/y2026/r5/6507/1651949/ | AM31: =IF(AJ31="","дані ще не вивантажені",IF('Бали кандидатів'!$B$7>=AJ31,"проходить","НЕ проходить за ЄВВ")) | AN31: =IF(AJ31="","дані ще не вивантажені",IF('Бали кандидатів'!$C$7>=AJ31,"проходить","НЕ проходить за ЄВВ"))
A32: F2 Інженерія ПЗ | B32: Харківський національний університет радіоелектроніки (ХНУРЕ) | C32: Харків | D32: Харківська | E32: ТАК | F32: Фіксована | G32: ні | I32: Інженерія програмного забезпечення | K32: 25 | L32: 45 | M32: =IF(K32=0,"н/д",L32/K32) | N32: 26.08.2026 | O32: 0.6 | P32: 0 | Q32: 0 | R32: 100 | S32: — | T32: =0.2*'Бали кандидатів'!$B$6+0.2*'Бали кандидатів'!$B$7+O32*'Бали кандидатів'!$B$9+P32*'Бали кандидатів'!$B$10+Q32*'Бали кандидатів'!$B$11 | U32: =0.2*'Бали кандидатів'!$C$6+0.2*'Бали кандидатів'!$C$7+O32*'Бали кандидатів'!$C$9+P32*'Бали кандидатів'!$C$10+Q32*'Бали кандидатів'!$C$11 | V32: =IF('Бали кандидатів'!$B$14>=300,"OK","НЕ ДОПУЩЕНО") | W32: =IF('Бали кандидатів'!$C$14>=300,"OK","НЕ ДОПУЩЕНО") | X32: =IF(AND(OR(R32="—",'Бали кандидатів'!$B$9>=R32),OR(S32="—",'Бали кандидатів'!$B$10>=S32)),"проходить","НИЖЧЕ мін. балу") | Y32: =IF(AND(OR(R32="—",'Бали кандидатів'!$C$9>=R32),OR(S32="—",'Бали кандидатів'!$C$10>=S32)),"проходить","НИЖЧЕ мін. балу") | Z32: Тільки іспит зі спеціальності | AE32: https://vstup.osvita.ua/r21/92/entrance.html | AF32: https://vstup.osvita.ua/y2026/r21/92/1653762/ | AM32: =IF(AJ32="","дані ще не вивантажені",IF('Бали кандидатів'!$B$7>=AJ32,"проходить","НЕ проходить за ЄВВ")) | AN32: =IF(AJ32="","дані ще не вивантажені",IF('Бали кандидатів'!$C$7>=AJ32,"проходить","НЕ проходить за ЄВВ"))
A33: F3 Комп'ютерні науки | B33: Харківський НУ міського господарства ім. О. М. Бекетова | C33: Харків | D33: Харківська | E33: ТАК | F33: Фіксована | G33: ні | I33: Комп'ютерні науки | J33: ННІ підготовки кадрів вищої кваліфікації | K33: 6 | L33: 11 | M33: =IF(K33=0,"н/д",L33/K33) | N33: 26.08.2026 | O33: 0.4 | P33: 0.2 | Q33: 0 | R33: — | S33: — | T33: =0.2*'Бали кандидатів'!$B$6+0.2*'Бали кандидатів'!$B$7+O33*'Бали кандидатів'!$B$9+P33*'Бали кандидатів'!$B$10+Q33*'Бали кандидатів'!$B$11 | U33: =0.2*'Бали кандидатів'!$C$6+0.2*'Бали кандидатів'!$C$7+O33*'Бали кандидатів'!$C$9+P33*'Бали кандидатів'!$C$10+Q33*'Бали кандидатів'!$C$11 | V33: =IF('Бали кандидатів'!$B$14>=300,"OK","НЕ ДОПУЩЕНО") | W33: =IF('Бали кандидатів'!$C$14>=300,"OK","НЕ ДОПУЩЕНО") | X33: =IF(AND(OR(R33="—",'Бали кандидатів'!$B$9>=R33),OR(S33="—",'Бали кандидатів'!$B$10>=S33)),"проходить","НИЖЧЕ мін. балу") | Y33: =IF(AND(OR(R33="—",'Бали кандидатів'!$C$9>=R33),OR(S33="—",'Бали кандидатів'!$C$10>=S33)),"проходить","НИЖЧЕ мін. балу") | Z33: Іспит + дослідницька пропозиція | AE33: https://vstup.osvita.ua/r21/316/entrance.html | AF33: https://vstup.osvita.ua/y2026/r21/316/1649777/ | AM33: =IF(AJ33="","дані ще не вивантажені",IF('Бали кандидатів'!$B$7>=AJ33,"проходить","НЕ проходить за ЄВВ")) | AN33: =IF(AJ33="","дані ще не вивантажені",IF('Бали кандидатів'!$C$7>=AJ33,"проходить","НЕ проходить за ЄВВ"))
A34: F4 Системний аналіз | B34: КПІ ім. Ігоря Сікорського | C34: Київ | D34: Київ | E34: ТАК | F34: Фіксована | G34: ні | I34: Системний аналіз | J34: ННІ прикладного системного аналізу | K34: 13 | L34: 24 | M34: =IF(K34=0,"н/д",L34/K34) | N34: 26.08.2026 | O34: ? | P34: ? | Q34: ? | R34: ? | S34: ? | T34: ваги невідомі | U34: ваги невідомі | V34: =IF('Бали кандидатів'!$B$14>=300,"OK","НЕ ДОПУЩЕНО") | W34: =IF('Бали кандидатів'!$C$14>=300,"OK","НЕ ДОПУЩЕНО") | X34: — | Y34: — | Z34: ваги не зчитані — уточнити на сторінці пропозиції | AA34: Складові конкурсного бала у вихідних даних відсутні — відкрити «Детальніше» на сторінці ЗВО | AE34: https://vstup.osvita.ua/r27/174/entrance.html | AF34: https://vstup.osvita.ua/r27/174/ | AM34: =IF(AJ34="","дані ще не вивантажені",IF('Бали кандидатів'!$B$7>=AJ34,"проходить","НЕ проходить за ЄВВ")) | AN34: =IF(AJ34="","дані ще не вивантажені",IF('Бали кандидатів'!$C$7>=AJ34,"проходить","НЕ проходить за ЄВВ"))
A35: F3 Комп'ютерні науки | B35: Український державний університет науки і технологій | C35: Дніпро | D35: Дніпропетровська | E35: ТАК | F35: Фіксована | G35: ні | I35: Комп'ютерні науки і технології | K35: 7 | L35: 13 | M35: =IF(K35=0,"н/д",L35/K35) | N35: 25.08.2026 (застаріле) | O35: 0.6 | P35: 0 | Q35: 0 | R35: — | S35: — | T35: =0.2*'Бали кандидатів'!$B$6+0.2*'Бали кандидатів'!$B$7+O35*'Бали кандидатів'!$B$9+P35*'Бали кандидатів'!$B$10+Q35*'Бали кандидатів'!$B$11 | U35: =0.2*'Бали кандидатів'!$C$6+0.2*'Бали кандидатів'!$C$7+O35*'Бали кандидатів'!$C$9+P35*'Бали кандидатів'!$C$10+Q35*'Бали кандидатів'!$C$11 | V35: =IF('Бали кандидатів'!$B$14>=300,"OK","НЕ ДОПУЩЕНО") | W35: =IF('Бали кандидатів'!$C$14>=300,"OK","НЕ ДОПУЩЕНО") | X35: =IF(AND(OR(R35="—",'Бали кандидатів'!$B$9>=R35),OR(S35="—",'Бали кандидатів'!$B$10>=S35)),"проходить","НИЖЧЕ мін. балу") | Y35: =IF(AND(OR(R35="—",'Бали кандидатів'!$C$9>=R35),OR(S35="—",'Бали кандидатів'!$C$10>=S35)),"проходить","НИЖЧЕ мін. балу") | Z35: Тільки іспит зі спеціальності | AE35: https://vstup.osvita.ua/r5/6507/entrance.html | AF35: https://vstup.osvita.ua/y2026/r5/6507/1653142/ | AM35: =IF(AJ35="","дані ще не вивантажені",IF('Бали кандидатів'!$B$7>=AJ35,"проходить","НЕ проходить за ЄВВ")) | AN35: =IF(AJ35="","дані ще не вивантажені",IF('Бали кандидатів'!$C$7>=AJ35,"проходить","НЕ проходить за ЄВВ"))
A36: F3 Комп'ютерні науки | B36: Державний університет «Житомирська політехніка» | C36: Житомир | D36: Житомирська | E36: ТАК | F36: Фіксована | G36: ні | I36: Комп'ютерні науки | J36: Інформаційно-комп'ютерних технологій | K36: 5 | L36: 10 | M36: =IF(K36=0,"н/д",L36/K36) | N36: 26.08.2026 | O36: 0.6 | P36: 0 | Q36: 0 | R36: 100 | S36: — | T36: =0.2*'Бали кандидатів'!$B$6+0.2*'Бали кандидатів'!$B$7+O36*'Бали кандидатів'!$B$9+P36*'Бали кандидатів'!$B$10+Q36*'Бали кандидатів'!$B$11 | U36: =0.2*'Бали кандидатів'!$C$6+0.2*'Бали кандидатів'!$C$7+O36*'Бали кандидатів'!$C$9+P36*'Бали кандидатів'!$C$10+Q36*'Бали кандидатів'!$C$11 | V36: =IF('Бали кандидатів'!$B$14>=300,"OK","НЕ ДОПУЩЕНО") | W36: =IF('Бали кандидатів'!$C$14>=300,"OK","НЕ ДОПУЩЕНО") | X36: =IF(AND(OR(R36="—",'Бали кандидатів'!$B$9>=R36),OR(S36="—",'Бали кандидатів'!$B$10>=S36)),"проходить","НИЖЧЕ мін. балу") | Y36: =IF(AND(OR(R36="—",'Бали кандидатів'!$C$9>=R36),OR(S36="—",'Бали кандидатів'!$C$10>=S36)),"проходить","НИЖЧЕ мін. балу") | Z36: Тільки іспит зі спеціальності | AA36: Додаткова співбесіда для вступників з іншої спеціальності (вага 0) | AE36: https://vstup.osvita.ua/r7/208/entrance.html | AF36: https://vstup.osvita.ua/y2026/r7/208/1653169/ | AM36: =IF(AJ36="","дані ще не вивантажені",IF('Бали кандидатів'!$B$7>=AJ36,"проходить","НЕ проходить за ЄВВ")) | AN36: =IF(AJ36="","дані ще не вивантажені",IF('Бали кандидатів'!$C$7>=AJ36,"проходить","НЕ проходить за ЄВВ"))
A37: F3 Комп'ютерні науки | B37: Інститут телекомунікацій і глобального інформаційного простору НАНУ | C37: Київ | D37: Київ | E37: ТАК | F37: Фіксована | G37: ні | I37: Інформаційні технології | K37: 4 | L37: 8 | M37: =IF(K37=0,"н/д",L37/K37) | N37: 26.08.2026 | O37: 0.6 | P37: 0 | Q37: 0 | R37: — | S37: — | T37: =0.2*'Бали кандидатів'!$B$6+0.2*'Бали кандидатів'!$B$7+O37*'Бали кандидатів'!$B$9+P37*'Бали кандидатів'!$B$10+Q37*'Бали кандидатів'!$B$11 | U37: =0.2*'Бали кандидатів'!$C$6+0.2*'Бали кандидатів'!$C$7+O37*'Бали кандидатів'!$C$9+P37*'Бали кандидатів'!$C$10+Q37*'Бали кандидатів'!$C$11 | V37: =IF('Бали кандидатів'!$B$14>=300,"OK","НЕ ДОПУЩЕНО") | W37: =IF('Бали кандидатів'!$C$14>=300,"OK","НЕ ДОПУЩЕНО") | X37: =IF(AND(OR(R37="—",'Бали кандидатів'!$B$9>=R37),OR(S37="—",'Бали кандидатів'!$B$10>=S37)),"проходить","НИЖЧЕ мін. балу") | Y37: =IF(AND(OR(R37="—",'Бали кандидатів'!$C$9>=R37),OR(S37="—",'Бали кандидатів'!$C$10>=S37)),"проходить","НИЖЧЕ мін. балу") | Z37: Тільки іспит зі спеціальності | AE37: https://vstup.osvita.ua/r27/3626/entrance.html | AF37: https://vstup.osvita.ua/y2026/r27/3626/1667883/ | AM37: =IF(AJ37="","дані ще не вивантажені",IF('Бали кандидатів'!$B$7>=AJ37,"проходить","НЕ проходить за ЄВВ")) | AN37: =IF(AJ37="","дані ще не вивантажені",IF('Бали кандидатів'!$C$7>=AJ37,"проходить","НЕ проходить за ЄВВ"))
A38: F3 Комп'ютерні науки | B38: Інститут інформаційних технологій та систем НАНУ | C38: Київ | D38: Київ | E38: ТАК | F38: Фіксована | G38: ні | I38: Інтелектуальні методи та засоби комп'ютерних наук | K38: 6 | L38: 12 | M38: =IF(K38=0,"н/д",L38/K38) | N38: 26.08.2026 | O38: 0.3 | P38: 0.3 | Q38: 0 | R38: 150 | S38: 120 | T38: =0.2*'Бали кандидатів'!$B$6+0.2*'Бали кандидатів'!$B$7+O38*'Бали кандидатів'!$B$9+P38*'Бали кандидатів'!$B$10+Q38*'Бали кандидатів'!$B$11 | U38: =0.2*'Бали кандидатів'!$C$6+0.2*'Бали кандидатів'!$C$7+O38*'Бали кандидатів'!$C$9+P38*'Бали кандидатів'!$C$10+Q38*'Бали кандидатів'!$C$11 | V38: =IF('Бали кандидатів'!$B$14>=300,"OK","НЕ ДОПУЩЕНО") | W38: =IF('Бали кандидатів'!$C$14>=300,"OK","НЕ ДОПУЩЕНО") | X38: =IF(AND(OR(R38="—",'Бали кандидатів'!$B$9>=R38),OR(S38="—",'Бали кандидатів'!$B$10>=S38)),"проходить","НИЖЧЕ мін. балу") | Y38: =IF(AND(OR(R38="—",'Бали кандидатів'!$C$9>=R38),OR(S38="—",'Бали кандидатів'!$C$10>=S38)),"проходить","НИЖЧЕ мін. балу") | Z38: Дослідницька пропозиція важить більше або нарівні з іспитом | AA38: Презентація оформлена як співбесіда: оцінювання дослідницької пропозиції ТА досвіду роботи; ЄВІ-іноземна і ТЗНК з мін. балом 150 | AE38: https://vstup.osvita.ua/r27/3746/entrance.html | AF38: https://vstup.osvita.ua/y2026/r27/3746/1650228/ | AM38: =IF(AJ38="","дані ще не вивантажені",IF('Бали кандидатів'!$B$7>=AJ38,"проходить","НЕ проходить за ЄВВ")) | AN38: =IF(AJ38="","дані ще не вивантажені",IF('Бали кандидатів'!$C$7>=AJ38,"проходить","НЕ проходить за ЄВВ"))
A39: F2 Інженерія ПЗ | B39: Державний університет «Житомирська політехніка» | C39: Житомир | D39: Житомирська | E39: ТАК | F39: Фіксована | G39: ні | I39: Інженерія програмного забезпечення | J39: Інформаційно-комп'ютерних технологій | K39: 5 | L39: 10 | M39: =IF(K39=0,"н/д",L39/K39) | N39: 26.08.2026 | O39: 0.6 | P39: 0 | Q39: 0 | R39: 100 | S39: — | T39: =0.2*'Бали кандидатів'!$B$6+0.2*'Бали кандидатів'!$B$7+O39*'Бали кандидатів'!$B$9+P39*'Бали кандидатів'!$B$10+Q39*'Бали кандидатів'!$B$11 | U39: =0.2*'Бали кандидатів'!$C$6+0.2*'Бали кандидатів'!$C$7+O39*'Бали кандидатів'!$C$9+P39*'Бали кандидатів'!$C$10+Q39*'Бали кандидатів'!$C$11 | V39: =IF('Бали кандидатів'!$B$14>=300,"OK","НЕ ДОПУЩЕНО") | W39: =IF('Бали кандидатів'!$C$14>=300,"OK","НЕ ДОПУЩЕНО") | X39: =IF(AND(OR(R39="—",'Бали кандидатів'!$B$9>=R39),OR(S39="—",'Бали кандидатів'!$B$10>=S39)),"проходить","НИЖЧЕ мін. балу") | Y39: =IF(AND(OR(R39="—",'Бали кандидатів'!$C$9>=R39),OR(S39="—",'Бали кандидатів'!$C$10>=S39)),"проходить","НИЖЧЕ мін. балу") | Z39: Тільки іспит зі спеціальності | AA39: Додаткова співбесіда для вступників з іншої спеціальності (вага 0) | AE39: https://vstup.osvita.ua/r7/208/entrance.html | AF39: https://vstup.osvita.ua/y2026/r7/208/1653165/ | AM39: =IF(AJ39="","дані ще не вивантажені",IF('Бали кандидатів'!$B$7>=AJ39,"проходить","НЕ проходить за ЄВВ")) | AN39: =IF(AJ39="","дані ще не вивантажені",IF('Бали кандидатів'!$C$7>=AJ39,"проходить","НЕ проходить за ЄВВ"))
A40: F4 Системний аналіз | B40: НТУ «Дніпровська політехніка» | C40: Дніпро | D40: Дніпропетровська | E40: ТАК | F40: Фіксована | G40: ні | I40: Системний аналіз | J40: Аспірантура і докторантура | K40: 3 | L40: 6 | M40: =IF(K40=0,"н/д",L40/K40) | N40: 26.08.2026 | O40: ? | P40: ? | Q40: ? | R40: ? | S40: ? | T40: ваги невідомі | U40: ваги невідомі | V40: =IF('Бали кандидатів'!$B$14>=300,"OK","НЕ ДОПУЩЕНО") | W40: =IF('Бали кандидатів'!$C$14>=300,"OK","НЕ ДОПУЩЕНО") | X40: — | Y40: — | Z40: ваги не зчитані — уточнити на сторінці пропозиції | AA40: Складові конкурсного бала у вихідних даних відсутні — відкрити «Детальніше» на сторінці ЗВО | AE40: https://vstup.osvita.ua/r5/36/entrance.html | AF40: https://vstup.osvita.ua/r5/36/ | AM40: =IF(AJ40="","дані ще не вивантажені",IF('Бали кандидатів'!$B$7>=AJ40,"проходить","НЕ проходить за ЄВВ")) | AN40: =IF(AJ40="","дані ще не вивантажені",IF('Бали кандидатів'!$C$7>=AJ40,"проходить","НЕ проходить за ЄВВ"))
...

Sheet Держзамовлення 2026
A1: БЮДЖЕТНІ МІСЦЯ В АСПІРАНТУРУ 2026 — що відомо офіційно
A3: Постанова КМУ від 13.07.2026 № 906. Усього на підготовку аспірантів — 6 073 бюджетні місця (у 2025 було 6 189). Розподіл ЗА ГАЛУЗЯМИ оприлюднено; розподіл МІЖ ЗАКЛАДАМИ здійснює конкурсна комісія МОН за формулою — торік це сталося аж 15 вересня, тобто вже після закриття подачі заяв.
A5: Галузь знань | B5: Бюджетних місць
A6: Інженерія, виробництво та будівництво | B6: 1616
A7: Природничі науки, математика та статистика | B7: 901
A8: Інформаційні технології ← сюди входить F3 Комп'ютерні науки | B8: 769
A9: Охорона здоров'я та соціальне забезпечення | B9: 548
A10: Соціальні науки, журналістика, інформація та міжнародні відносини | B10: 489
A11: Культура, мистецтво та гуманітарні науки | B11: 437
A12: Освіта | B12: 385
A13: Сільське, лісове, рибне господарство та ветеринарна медицина | B13: 366
A14: Бізнес, адміністрування та право | B14: 354
A15: Безпека та оборона | B15: 108
A16: Транспорт та послуги | B16: 100
A17: РАЗОМ | B17: =SUM(B6:B16)
A19: ЩО З ЦЬОГО ВИПЛИВАЄ ДЛЯ F3
A20: 769 місць — це на ВСЮ галузь «Інформаційні технології», а в ній сім спеціальностей: F1 Прикладна математика, F2 Інженерія ПЗ, F3 Комп'ютерні науки, F4 Системний аналіз, F5 Кібербезпека, F6 Інформаційні системи, F7 Комп'ютерна інженерія.
A21: Отже на F3 по всій Україні реально припадає помітно менше за 769 — і суттєво менше за 538 ліцензованих місць, які показує другий аркуш.
A22: На вступні випробування до аспірантури цьогоріч зареєструвалося понад 20 тис. осіб (на чверть більше, ніж торік) на 6 073 місця — приблизно 3,3 претендента на місце по країні.
A23: Вступ на денну форму на контракт неможливий — денна лише за держзамовленням.
A24: Скільки місць отримає конкретний ЗВО за галуззю IT — стане відомо ближче до середини вересня, тобто ВЖЕ ПІСЛЯ того, як ви подасте заяви (дедлайн 7 вересня). Це не помилка даних, а порядок процесу.
A25: Практичний висновок: подавайте всі 5 бюджетних заяв і не покладайтеся на одну «безпечну» пропозицію — кількість місць у ній на момент подачі ще не визначена.
A26: Джерела: Постанова КМУ № 906 від 13.07.2026; МОН, наказ № 863 від 17.06.2025 про критерії розподілу.

Sheet Джерела
A1: ДЖЕРЕЛА — усе, звідки взято дані в цьому файлі
A3: Перевірено 25.08.2026. Дані вступної кампанії змінюються щодня — перед подачею звіряйте.
A5: Що саме звідти взято | B5: Посилання | C5: Статус
A6: ОФІЦІЙНІ ДОКУМЕНТИ
A7: Правила прийому до ЛНУ ім. Франка 2026 (повний текст, PDF): формула КБ, умови дистанційного складання, ліміт заяв | B7: https://admission.lnu.edu.ua/wp-content/uploads/2026/07/PP_2026_n.pdf | C7: перевірено
A8: Правила прийому ЛНУ — головна сторінка з усіма додатками | B8: https://admission.lnu.edu.ua/guidelines-for-admission/ | C8: перевірено
A9: Графік вступних іспитів PhD у Львівській політехніці 2026 (F3 — 09.09.2026, 14:30, І корпус, Старосольських 2/4). Оновлено 06.08.2026 | B9: https://lpnu.ua/sites/default/files/2020/pages/1867/aspiranturagrafik-provedennya-vstupnikh-ispitiv06082026.pdf | C9: перевірено
A10: Сторінка «Обсяги державного замовлення» Львівської політехніки — досі лише файл за 2025 рік (оновлено 11 місяців тому). Пряме підтвердження, що розподіл-2026 ще не опубліковано | B10: https://lpnu.ua/aspirantam/vstup/obsiagy-derzhavnogo-zamovlennia | C10: перевірено 25.08.2026
A11: Програми вступних іспитів зі спеціальності PhD, Львівська політехніка (затверджені 01.05.2026) | B11: https://lpnu.ua/aspirantam/vstup/prohramy-vstupnykh-ispytiv-zi-spetsialnosti | C11: перевірено
A12: Розклад вступних іспитів зі спеціальності PhD у ЛНУ (F3 — 19.09.2026, 14:00) | B12: https://admission.lnu.edu.ua/wp-content/uploads/2026/08/Rozklad-PhD.pdf | C12: перевірено
